2021-12-02 14:01:14,576 ERROR    Uncaught exception: [Errno 8] Exec format error: './truthtable'
Traceback (most recent call last):
  File "/Users/user/Applications/comp-arch/pa4/autograde.py", line 973, in main
    test_project(assignment, src_dir, build_dir, data_dir, **kws)
  File "/Users/user/Applications/comp-arch/pa4/autograde.py", line 743, in test_project
    (success, credit) = t.run()
  File "/Users/user/Applications/comp-arch/pa4/autograde.py", line 150, in run
    encoding = self.encoding)
  File "/Users/user/opt/anaconda3/envs/ai-service/lib/python3.7/subprocess.py", line 800, in __init__
    restore_signals, start_new_session)
  File "/Users/user/opt/anaconda3/envs/ai-service/lib/python3.7/subprocess.py", line 1551, in _execute_child
    raise child_exception_type(errno_num, err_msg, err_filename)
OSError: [Errno 8] Exec format error: './truthtable'
